Epoch 1/10:   0%|                                                                                                     | 0/1104 [00:28<?, ?it/s]
Traceback (most recent call last):
  File "/home/zeus/miniconda3/envs/cloudspace/lib/python3.10/site-packages/torch/utils/data/dataloader.py", line 631, in __next__
    data = self._next_data()
  File "/home/zeus/miniconda3/envs/cloudspace/lib/python3.10/site-packages/torch/utils/data/dataloader.py", line 1329, in _next_data
    idx, data = self._get_data()
  File "/home/zeus/miniconda3/envs/cloudspace/lib/python3.10/site-packages/torch/utils/data/dataloader.py", line 1295, in _get_data
    success, data = self._try_get_data()
  File "/home/zeus/miniconda3/envs/cloudspace/lib/python3.10/site-packages/torch/utils/data/dataloader.py", line 1133, in _try_get_data
    data = self._data_queue.get(timeout=timeout)
  File "/home/zeus/miniconda3/envs/cloudspace/lib/python3.10/multiprocessing/queues.py", line 113, in get
    if not self._poll(timeout):
  File "/home/zeus/miniconda3/envs/cloudspace/lib/python3.10/multiprocessing/connection.py", line 257, in poll
    return self._poll(timeout)
  File "/home/zeus/miniconda3/envs/cloudspace/lib/python3.10/multiprocessing/connection.py", line 424, in _poll
    r = wait([self], timeout)
  File "/home/zeus/miniconda3/envs/cloudspace/lib/python3.10/multiprocessing/connection.py", line 931, in wait
    ready = selector.select(timeout)
  File "/home/zeus/miniconda3/envs/cloudspace/lib/python3.10/selectors.py", line 416, in select
    fd_event_list = self._selector.poll(timeout)
KeyboardInterrupt

During handling of the above exception, another exception occurred:

Traceback (most recent call last):
  File "/teamspace/studios/this_studio/ileri_sayisal/train_hf.py", line 178, in <module>
    finetuner.train(train_loader, val_loader)
  File "/teamspace/studios/this_studio/ileri_sayisal/train_hf.py", line 70, in train
    for batch in pbar:
  File "/home/zeus/miniconda3/envs/cloudspace/lib/python3.10/site-packages/tqdm/std.py", line 1181, in __iter__
    for obj in iterable:
  File "/home/zeus/miniconda3/envs/cloudspace/lib/python3.10/site-packages/torch/utils/data/dataloader.py", line 627, in __next__
    with torch.autograd.profiler.record_function(self._profile_name):
  File "/home/zeus/miniconda3/envs/cloudspace/lib/python3.10/site-packages/torch/autograd/profiler.py", line 622, in __exit__
    torch.ops.profiler._record_function_exit._RecordFunction(record)
  File "/home/zeus/miniconda3/envs/cloudspace/lib/python3.10/site-packages/torch/_ops.py", line 513, in __call__
    return self._op(*args, **(kwargs or {}))
KeyboardInterrupt
Traceback (most recent call last):
  File "/home/zeus/miniconda3/envs/cloudspace/lib/python3.10/site-packages/torch/utils/data/dataloader.py", line 631, in __next__
    data = self._next_data()
  File "/home/zeus/miniconda3/envs/cloudspace/lib/python3.10/site-packages/torch/utils/data/dataloader.py", line 1329, in _next_data
    idx, data = self._get_data()
  File "/home/zeus/miniconda3/envs/cloudspace/lib/python3.10/site-packages/torch/utils/data/dataloader.py", line 1295, in _get_data
    success, data = self._try_get_data()
  File "/home/zeus/miniconda3/envs/cloudspace/lib/python3.10/site-packages/torch/utils/data/dataloader.py", line 1133, in _try_get_data
    data = self._data_queue.get(timeout=timeout)
  File "/home/zeus/miniconda3/envs/cloudspace/lib/python3.10/multiprocessing/queues.py", line 113, in get
    if not self._poll(timeout):
  File "/home/zeus/miniconda3/envs/cloudspace/lib/python3.10/multiprocessing/connection.py", line 257, in poll
    return self._poll(timeout)
  File "/home/zeus/miniconda3/envs/cloudspace/lib/python3.10/multiprocessing/connection.py", line 424, in _poll
    r = wait([self], timeout)
  File "/home/zeus/miniconda3/envs/cloudspace/lib/python3.10/multiprocessing/connection.py", line 931, in wait
    ready = selector.select(timeout)
  File "/home/zeus/miniconda3/envs/cloudspace/lib/python3.10/selectors.py", line 416, in select
    fd_event_list = self._selector.poll(timeout)
KeyboardInterrupt

During handling of the above exception, another exception occurred:

Traceback (most recent call last):
  File "/teamspace/studios/this_studio/ileri_sayisal/train_hf.py", line 178, in <module>
    finetuner.train(train_loader, val_loader)
  File "/teamspace/studios/this_studio/ileri_sayisal/train_hf.py", line 70, in train
    for batch in pbar:
  File "/home/zeus/miniconda3/envs/cloudspace/lib/python3.10/site-packages/tqdm/std.py", line 1181, in __iter__
    for obj in iterable:
  File "/home/zeus/miniconda3/envs/cloudspace/lib/python3.10/site-packages/torch/utils/data/dataloader.py", line 627, in __next__
    with torch.autograd.profiler.record_function(self._profile_name):
  File "/home/zeus/miniconda3/envs/cloudspace/lib/python3.10/site-packages/torch/autograd/profiler.py", line 622, in __exit__
    torch.ops.profiler._record_function_exit._RecordFunction(record)
  File "/home/zeus/miniconda3/envs/cloudspace/lib/python3.10/site-packages/torch/_ops.py", line 513, in __call__
    return self._op(*args, **(kwargs or {}))
KeyboardInterrupt
